const x = 10

try {
  let x = 2
} catch(err) {
  console.log(`Erro: $${err}`)
}